{
 "cells": [
  {
   "cell_type": "code",
   "execution_count": 12,
   "id": "8a9e0570-99c7-48b9-ad19-0c70a84142b2",
   "metadata": {},
   "outputs": [
    {
     "name": "stderr",
     "output_type": "stream",
     "text": [
      "All PyTorch model weights were used when initializing TFBertForSequenceClassification.\n",
      "\n",
      "Some weights or buffers of the TF 2.0 model TFBertForSequenceClassification were not initialized from the PyTorch model and are newly initialized: ['classifier.weight', 'classifier.bias']\n",
      "You should probably TRAIN this model on a down-stream task to be able to use it for predictions and inference.\n",
      "WARNING:absl:At this time, the v2.11+ optimizer `tf.keras.optimizers.Adam` runs slowly on M1/M2 Macs, please use the legacy TF-Keras optimizer instead, located at `tf.keras.optimizers.legacy.Adam`.\n"
     ]
    },
    {
     "name": "stdout",
     "output_type": "stream",
     "text": [
      "Epoch 1/3\n"
     ]
    },
    {
     "name": "stderr",
     "output_type": "stream",
     "text": [
      "2024-06-29 04:40:01.486975: W tensorflow/core/framework/op_kernel.cc:1839] OP_REQUIRES failed at sparse_xent_op.cc:103 : INVALID_ARGUMENT: Received a label value of 2 which is outside the valid range of [0, 2).  Label values: 1 2 1 1 0 2 2 2 2 2 2 1 0 2 2 2\n",
      "2024-06-29 04:40:01.487116: W tensorflow/core/framework/local_rendezvous.cc:404] Local rendezvous is aborting with status: INVALID_ARGUMENT: Received a label value of 2 which is outside the valid range of [0, 2).  Label values: 1 2 1 1 0 2 2 2 2 2 2 1 0 2 2 2\n",
      "\t [[{{node sparse_categorical_crossentropy/SparseSoftmaxCrossEntropyWithLogits/SparseSoftmaxCrossEntropyWithLogits}}]]\n"
     ]
    },
    {
     "ename": "InvalidArgumentError",
     "evalue": "Graph execution error:\n\nDetected at node sparse_categorical_crossentropy/SparseSoftmaxCrossEntropyWithLogits/SparseSoftmaxCrossEntropyWithLogits defined at (most recent call last):\n  File \"<frozen runpy>\", line 198, in _run_module_as_main\n\n  File \"<frozen runpy>\", line 88, in _run_code\n\n  File \"/opt/anaconda3/lib/python3.11/site-packages/ipykernel_launcher.py\", line 17, in <module>\n\n  File \"/opt/anaconda3/lib/python3.11/site-packages/traitlets/config/application.py\", line 992, in launch_instance\n\n  File \"/opt/anaconda3/lib/python3.11/site-packages/ipykernel/kernelapp.py\", line 701, in start\n\n  File \"/opt/anaconda3/lib/python3.11/site-packages/tornado/platform/asyncio.py\", line 195, in start\n\n  File \"/opt/anaconda3/lib/python3.11/asyncio/base_events.py\", line 607, in run_forever\n\n  File \"/opt/anaconda3/lib/python3.11/asyncio/base_events.py\", line 1922, in _run_once\n\n  File \"/opt/anaconda3/lib/python3.11/asyncio/events.py\", line 80, in _run\n\n  File \"/opt/anaconda3/lib/python3.11/site-packages/ipykernel/kernelbase.py\", line 534, in dispatch_queue\n\n  File \"/opt/anaconda3/lib/python3.11/site-packages/ipykernel/kernelbase.py\", line 523, in process_one\n\n  File \"/opt/anaconda3/lib/python3.11/site-packages/ipykernel/kernelbase.py\", line 429, in dispatch_shell\n\n  File \"/opt/anaconda3/lib/python3.11/site-packages/ipykernel/kernelbase.py\", line 767, in execute_request\n\n  File \"/opt/anaconda3/lib/python3.11/site-packages/ipykernel/ipkernel.py\", line 429, in do_execute\n\n  File \"/opt/anaconda3/lib/python3.11/site-packages/ipykernel/zmqshell.py\", line 549, in run_cell\n\n  File \"/opt/anaconda3/lib/python3.11/site-packages/IPython/core/interactiveshell.py\", line 3051, in run_cell\n\n  File \"/opt/anaconda3/lib/python3.11/site-packages/IPython/core/interactiveshell.py\", line 3106, in _run_cell\n\n  File \"/opt/anaconda3/lib/python3.11/site-packages/IPython/core/async_helpers.py\", line 129, in _pseudo_sync_runner\n\n  File \"/opt/anaconda3/lib/python3.11/site-packages/IPython/core/interactiveshell.py\", line 3311, in run_cell_async\n\n  File \"/opt/anaconda3/lib/python3.11/site-packages/IPython/core/interactiveshell.py\", line 3493, in run_ast_nodes\n\n  File \"/opt/anaconda3/lib/python3.11/site-packages/IPython/core/interactiveshell.py\", line 3553, in run_code\n\n  File \"/var/folders/zr/9nk9f84s70qf1fpvdqxnh_j80000gn/T/ipykernel_21747/3618678403.py\", line 54, in <module>\n\n  File \"/opt/anaconda3/lib/python3.11/site-packages/transformers/modeling_tf_utils.py\", line 1229, in fit\n\n  File \"/opt/anaconda3/lib/python3.11/site-packages/tf_keras/src/utils/traceback_utils.py\", line 65, in error_handler\n\n  File \"/opt/anaconda3/lib/python3.11/site-packages/tf_keras/src/engine/training.py\", line 1804, in fit\n\n  File \"/opt/anaconda3/lib/python3.11/site-packages/tf_keras/src/engine/training.py\", line 1398, in train_function\n\n  File \"/opt/anaconda3/lib/python3.11/site-packages/tf_keras/src/engine/training.py\", line 1381, in step_function\n\n  File \"/opt/anaconda3/lib/python3.11/site-packages/tf_keras/src/engine/training.py\", line 1370, in run_step\n\n  File \"/opt/anaconda3/lib/python3.11/site-packages/transformers/modeling_tf_utils.py\", line 1705, in train_step\n\n  File \"/opt/anaconda3/lib/python3.11/site-packages/transformers/modeling_tf_utils.py\", line 1706, in train_step\n\n  File \"/opt/anaconda3/lib/python3.11/site-packages/tf_keras/src/engine/compile_utils.py\", line 269, in __call__\n\n  File \"/opt/anaconda3/lib/python3.11/site-packages/tf_keras/src/engine/compile_utils.py\", line 269, in __call__\n\n  File \"/opt/anaconda3/lib/python3.11/site-packages/tf_keras/src/engine/compile_utils.py\", line 277, in __call__\n\n  File \"/opt/anaconda3/lib/python3.11/site-packages/tf_keras/src/losses.py\", line 143, in __call__\n\n  File \"/opt/anaconda3/lib/python3.11/site-packages/tf_keras/src/losses.py\", line 270, in call\n\n  File \"/opt/anaconda3/lib/python3.11/site-packages/tf_keras/src/losses.py\", line 2454, in sparse_categorical_crossentropy\n\n  File \"/opt/anaconda3/lib/python3.11/site-packages/tf_keras/src/backend.py\", line 5777, in sparse_categorical_crossentropy\n\nReceived a label value of 2 which is outside the valid range of [0, 2).  Label values: 1 2 1 1 0 2 2 2 2 2 2 1 0 2 2 2\n\t [[{{node sparse_categorical_crossentropy/SparseSoftmaxCrossEntropyWithLogits/SparseSoftmaxCrossEntropyWithLogits}}]] [Op:__inference_train_function_78226]",
     "output_type": "error",
     "traceback": [
      "\u001b[0;31m---------------------------------------------------------------------------\u001b[0m",
      "\u001b[0;31mInvalidArgumentError\u001b[0m                      Traceback (most recent call last)",
      "Cell \u001b[0;32mIn[12], line 54\u001b[0m\n\u001b[1;32m     49\u001b[0m model\u001b[38;5;241m.\u001b[39mcompile(optimizer\u001b[38;5;241m=\u001b[39mtf\u001b[38;5;241m.\u001b[39mkeras\u001b[38;5;241m.\u001b[39moptimizers\u001b[38;5;241m.\u001b[39mAdam(learning_rate\u001b[38;5;241m=\u001b[39m\u001b[38;5;241m1e-5\u001b[39m),\n\u001b[1;32m     50\u001b[0m               loss\u001b[38;5;241m=\u001b[39mtf\u001b[38;5;241m.\u001b[39mkeras\u001b[38;5;241m.\u001b[39mlosses\u001b[38;5;241m.\u001b[39mSparseCategoricalCrossentropy(from_logits\u001b[38;5;241m=\u001b[39m\u001b[38;5;28;01mTrue\u001b[39;00m),\n\u001b[1;32m     51\u001b[0m               metrics\u001b[38;5;241m=\u001b[39m[tf\u001b[38;5;241m.\u001b[39mkeras\u001b[38;5;241m.\u001b[39mmetrics\u001b[38;5;241m.\u001b[39mSparseCategoricalAccuracy(\u001b[38;5;124m'\u001b[39m\u001b[38;5;124maccuracy\u001b[39m\u001b[38;5;124m'\u001b[39m)])\n\u001b[1;32m     53\u001b[0m \u001b[38;5;66;03m# Train the model\u001b[39;00m\n\u001b[0;32m---> 54\u001b[0m history \u001b[38;5;241m=\u001b[39m model\u001b[38;5;241m.\u001b[39mfit(train_dataset, epochs\u001b[38;5;241m=\u001b[39m\u001b[38;5;241m3\u001b[39m, validation_data\u001b[38;5;241m=\u001b[39mtest_dataset)\n\u001b[1;32m     56\u001b[0m \u001b[38;5;66;03m# Evaluate model performance\u001b[39;00m\n\u001b[1;32m     57\u001b[0m predictions \u001b[38;5;241m=\u001b[39m model\u001b[38;5;241m.\u001b[39mpredict(test_dataset)\n",
      "File \u001b[0;32m/opt/anaconda3/lib/python3.11/site-packages/transformers/modeling_tf_utils.py:1229\u001b[0m, in \u001b[0;36mTFPreTrainedModel.fit\u001b[0;34m(self, *args, **kwargs)\u001b[0m\n\u001b[1;32m   1226\u001b[0m \u001b[38;5;129m@functools\u001b[39m\u001b[38;5;241m.\u001b[39mwraps(keras\u001b[38;5;241m.\u001b[39mModel\u001b[38;5;241m.\u001b[39mfit)\n\u001b[1;32m   1227\u001b[0m \u001b[38;5;28;01mdef\u001b[39;00m \u001b[38;5;21mfit\u001b[39m(\u001b[38;5;28mself\u001b[39m, \u001b[38;5;241m*\u001b[39margs, \u001b[38;5;241m*\u001b[39m\u001b[38;5;241m*\u001b[39mkwargs):\n\u001b[1;32m   1228\u001b[0m     args, kwargs \u001b[38;5;241m=\u001b[39m convert_batch_encoding(\u001b[38;5;241m*\u001b[39margs, \u001b[38;5;241m*\u001b[39m\u001b[38;5;241m*\u001b[39mkwargs)\n\u001b[0;32m-> 1229\u001b[0m     \u001b[38;5;28;01mreturn\u001b[39;00m \u001b[38;5;28msuper\u001b[39m()\u001b[38;5;241m.\u001b[39mfit(\u001b[38;5;241m*\u001b[39margs, \u001b[38;5;241m*\u001b[39m\u001b[38;5;241m*\u001b[39mkwargs)\n",
      "File \u001b[0;32m/opt/anaconda3/lib/python3.11/site-packages/tf_keras/src/utils/traceback_utils.py:70\u001b[0m, in \u001b[0;36mfilter_traceback.<locals>.error_handler\u001b[0;34m(*args, **kwargs)\u001b[0m\n\u001b[1;32m     67\u001b[0m     filtered_tb \u001b[38;5;241m=\u001b[39m _process_traceback_frames(e\u001b[38;5;241m.\u001b[39m__traceback__)\n\u001b[1;32m     68\u001b[0m     \u001b[38;5;66;03m# To get the full stack trace, call:\u001b[39;00m\n\u001b[1;32m     69\u001b[0m     \u001b[38;5;66;03m# `tf.debugging.disable_traceback_filtering()`\u001b[39;00m\n\u001b[0;32m---> 70\u001b[0m     \u001b[38;5;28;01mraise\u001b[39;00m e\u001b[38;5;241m.\u001b[39mwith_traceback(filtered_tb) \u001b[38;5;28;01mfrom\u001b[39;00m \u001b[38;5;28;01mNone\u001b[39;00m\n\u001b[1;32m     71\u001b[0m \u001b[38;5;28;01mfinally\u001b[39;00m:\n\u001b[1;32m     72\u001b[0m     \u001b[38;5;28;01mdel\u001b[39;00m filtered_tb\n",
      "File \u001b[0;32m/opt/anaconda3/lib/python3.11/site-packages/tensorflow/python/eager/execute.py:53\u001b[0m, in \u001b[0;36mquick_execute\u001b[0;34m(op_name, num_outputs, inputs, attrs, ctx, name)\u001b[0m\n\u001b[1;32m     51\u001b[0m \u001b[38;5;28;01mtry\u001b[39;00m:\n\u001b[1;32m     52\u001b[0m   ctx\u001b[38;5;241m.\u001b[39mensure_initialized()\n\u001b[0;32m---> 53\u001b[0m   tensors \u001b[38;5;241m=\u001b[39m pywrap_tfe\u001b[38;5;241m.\u001b[39mTFE_Py_Execute(ctx\u001b[38;5;241m.\u001b[39m_handle, device_name, op_name,\n\u001b[1;32m     54\u001b[0m                                       inputs, attrs, num_outputs)\n\u001b[1;32m     55\u001b[0m \u001b[38;5;28;01mexcept\u001b[39;00m core\u001b[38;5;241m.\u001b[39m_NotOkStatusException \u001b[38;5;28;01mas\u001b[39;00m e:\n\u001b[1;32m     56\u001b[0m   \u001b[38;5;28;01mif\u001b[39;00m name \u001b[38;5;129;01mis\u001b[39;00m \u001b[38;5;129;01mnot\u001b[39;00m \u001b[38;5;28;01mNone\u001b[39;00m:\n",
      "\u001b[0;31mInvalidArgumentError\u001b[0m: Graph execution error:\n\nDetected at node sparse_categorical_crossentropy/SparseSoftmaxCrossEntropyWithLogits/SparseSoftmaxCrossEntropyWithLogits defined at (most recent call last):\n  File \"<frozen runpy>\", line 198, in _run_module_as_main\n\n  File \"<frozen runpy>\", line 88, in _run_code\n\n  File \"/opt/anaconda3/lib/python3.11/site-packages/ipykernel_launcher.py\", line 17, in <module>\n\n  File \"/opt/anaconda3/lib/python3.11/site-packages/traitlets/config/application.py\", line 992, in launch_instance\n\n  File \"/opt/anaconda3/lib/python3.11/site-packages/ipykernel/kernelapp.py\", line 701, in start\n\n  File \"/opt/anaconda3/lib/python3.11/site-packages/tornado/platform/asyncio.py\", line 195, in start\n\n  File \"/opt/anaconda3/lib/python3.11/asyncio/base_events.py\", line 607, in run_forever\n\n  File \"/opt/anaconda3/lib/python3.11/asyncio/base_events.py\", line 1922, in _run_once\n\n  File \"/opt/anaconda3/lib/python3.11/asyncio/events.py\", line 80, in _run\n\n  File \"/opt/anaconda3/lib/python3.11/site-packages/ipykernel/kernelbase.py\", line 534, in dispatch_queue\n\n  File \"/opt/anaconda3/lib/python3.11/site-packages/ipykernel/kernelbase.py\", line 523, in process_one\n\n  File \"/opt/anaconda3/lib/python3.11/site-packages/ipykernel/kernelbase.py\", line 429, in dispatch_shell\n\n  File \"/opt/anaconda3/lib/python3.11/site-packages/ipykernel/kernelbase.py\", line 767, in execute_request\n\n  File \"/opt/anaconda3/lib/python3.11/site-packages/ipykernel/ipkernel.py\", line 429, in do_execute\n\n  File \"/opt/anaconda3/lib/python3.11/site-packages/ipykernel/zmqshell.py\", line 549, in run_cell\n\n  File \"/opt/anaconda3/lib/python3.11/site-packages/IPython/core/interactiveshell.py\", line 3051, in run_cell\n\n  File \"/opt/anaconda3/lib/python3.11/site-packages/IPython/core/interactiveshell.py\", line 3106, in _run_cell\n\n  File \"/opt/anaconda3/lib/python3.11/site-packages/IPython/core/async_helpers.py\", line 129, in _pseudo_sync_runner\n\n  File \"/opt/anaconda3/lib/python3.11/site-packages/IPython/core/interactiveshell.py\", line 3311, in run_cell_async\n\n  File \"/opt/anaconda3/lib/python3.11/site-packages/IPython/core/interactiveshell.py\", line 3493, in run_ast_nodes\n\n  File \"/opt/anaconda3/lib/python3.11/site-packages/IPython/core/interactiveshell.py\", line 3553, in run_code\n\n  File \"/var/folders/zr/9nk9f84s70qf1fpvdqxnh_j80000gn/T/ipykernel_21747/3618678403.py\", line 54, in <module>\n\n  File \"/opt/anaconda3/lib/python3.11/site-packages/transformers/modeling_tf_utils.py\", line 1229, in fit\n\n  File \"/opt/anaconda3/lib/python3.11/site-packages/tf_keras/src/utils/traceback_utils.py\", line 65, in error_handler\n\n  File \"/opt/anaconda3/lib/python3.11/site-packages/tf_keras/src/engine/training.py\", line 1804, in fit\n\n  File \"/opt/anaconda3/lib/python3.11/site-packages/tf_keras/src/engine/training.py\", line 1398, in train_function\n\n  File \"/opt/anaconda3/lib/python3.11/site-packages/tf_keras/src/engine/training.py\", line 1381, in step_function\n\n  File \"/opt/anaconda3/lib/python3.11/site-packages/tf_keras/src/engine/training.py\", line 1370, in run_step\n\n  File \"/opt/anaconda3/lib/python3.11/site-packages/transformers/modeling_tf_utils.py\", line 1705, in train_step\n\n  File \"/opt/anaconda3/lib/python3.11/site-packages/transformers/modeling_tf_utils.py\", line 1706, in train_step\n\n  File \"/opt/anaconda3/lib/python3.11/site-packages/tf_keras/src/engine/compile_utils.py\", line 269, in __call__\n\n  File \"/opt/anaconda3/lib/python3.11/site-packages/tf_keras/src/engine/compile_utils.py\", line 269, in __call__\n\n  File \"/opt/anaconda3/lib/python3.11/site-packages/tf_keras/src/engine/compile_utils.py\", line 277, in __call__\n\n  File \"/opt/anaconda3/lib/python3.11/site-packages/tf_keras/src/losses.py\", line 143, in __call__\n\n  File \"/opt/anaconda3/lib/python3.11/site-packages/tf_keras/src/losses.py\", line 270, in call\n\n  File \"/opt/anaconda3/lib/python3.11/site-packages/tf_keras/src/losses.py\", line 2454, in sparse_categorical_crossentropy\n\n  File \"/opt/anaconda3/lib/python3.11/site-packages/tf_keras/src/backend.py\", line 5777, in sparse_categorical_crossentropy\n\nReceived a label value of 2 which is outside the valid range of [0, 2).  Label values: 1 2 1 1 0 2 2 2 2 2 2 1 0 2 2 2\n\t [[{{node sparse_categorical_crossentropy/SparseSoftmaxCrossEntropyWithLogits/SparseSoftmaxCrossEntropyWithLogits}}]] [Op:__inference_train_function_78226]"
     ]
    }
   ],
   "source": [
    "import pandas as pd\n",
    "import tensorflow as tf\n",
    "from sklearn.model_selection import train_test_split\n",
    "from sklearn.metrics import classification_report\n",
    "from transformers import TFBertForSequenceClassification, BertTokenizer\n",
    "\n",
    "# Load preprocessed data\n",
    "df = pd.read_csv('preprocessed_tweets_dataset.csv')\n",
    "\n",
    "# Mapping categorical labels to integers\n",
    "label_map = {'Negative': 0, 'Neutral': 1, 'Positive': 2}\n",
    "df['label'] = df['Sentiment'].map(label_map)\n",
    "\n",
    "# Split data into train and test sets\n",
    "train_texts, test_texts, train_labels, test_labels = train_test_split(\n",
    "    df['preprocessed_text'], df['label'], test_size=0.2, random_state=42)\n",
    "\n",
    "# Convert train_texts and test_texts to lists of strings\n",
    "train_texts = train_texts.astype(str).tolist()\n",
    "test_texts = test_texts.astype(str).tolist()\n",
    "\n",
    "# Initialize BERT tokenizer\n",
    "model_name = 'bert-base-uncased'\n",
    "tokenizer = BertTokenizer.from_pretrained(model_name)\n",
    "\n",
    "# Tokenize text data\n",
    "train_encodings = tokenizer(train_texts, truncation=True, padding=True)\n",
    "test_encodings = tokenizer(test_texts, truncation=True, padding=True)\n",
    "\n",
    "# Ensure train_labels and test_labels are integers\n",
    "train_labels = train_labels.astype(int).values\n",
    "test_labels = test_labels.astype(int).values\n",
    "\n",
    "# Create TensorFlow datasets\n",
    "train_dataset = tf.data.Dataset.from_tensor_slices((\n",
    "    dict(train_encodings),\n",
    "    train_labels\n",
    ")).shuffle(len(train_texts)).batch(16)\n",
    "\n",
    "test_dataset = tf.data.Dataset.from_tensor_slices((\n",
    "    dict(test_encodings),\n",
    "    test_labels\n",
    ")).batch(16)\n",
    "\n",
    "# Load pre-trained BERT model for sequence classification\n",
    "model = TFBertForSequenceClassification.from_pretrained(model_name)\n",
    "\n",
    "# Define model compile and training\n",
    "model.compile(optimizer=tf.keras.optimizers.Adam(learning_rate=1e-5),\n",
    "              loss=tf.keras.losses.SparseCategoricalCrossentropy(from_logits=True),\n",
    "              metrics=[tf.keras.metrics.SparseCategoricalAccuracy('accuracy')])\n",
    "\n",
    "# Train the model\n",
    "history = model.fit(train_dataset, epochs=3, validation_data=test_dataset)\n",
    "\n",
    "# Evaluate model performance\n",
    "predictions = model.predict(test_dataset)\n",
    "predicted_labels = tf.argmax(predictions.logits, axis=1)\n",
    "print(classification_report(test_labels, predicted_labels.numpy(), target_names=['Negative', 'Neutral', 'Positive']))\n",
    "\n",
    "# Save model training and evaluation information in documentation file (README.md)\n",
    "model_training_info = \"\"\"\n",
    "### Model Training and Evaluation\n",
    "\n",
    "- **Model:** Fine-tuned BERT for Sequence Classification\n",
    "- **Metrics:** Accuracy, Precision, Recall, F1 Score\n",
    "\"\"\"\n",
    "with open('README.md', 'a') as readme_file:\n",
    "    readme_file.write(model_training_info)\n"
   ]
  },
  {
   "cell_type": "code",
   "execution_count": null,
   "id": "5904ba5e-a3fa-4967-98c0-242b41279493",
   "metadata": {},
   "outputs": [],
   "source": []
  },
  {
   "cell_type": "code",
   "execution_count": null,
   "id": "c3276629-a791-49a2-8bea-1b33316a3fdd",
   "metadata": {},
   "outputs": [],
   "source": []
  },
  {
   "cell_type": "code",
   "execution_count": null,
   "id": "d3c1e54a-29f7-4f03-bb0c-d3e96b9c34c2",
   "metadata": {},
   "outputs": [],
   "source": []
  }
 ],
 "metadata": {
  "kernelspec": {
   "display_name": "Python 3 (ipykernel)",
   "language": "python",
   "name": "python3"
  },
  "language_info": {
   "codemirror_mode": {
    "name": "ipython",
    "version": 3
   },
   "file_extension": ".py",
   "mimetype": "text/x-python",
   "name": "python",
   "nbconvert_exporter": "python",
   "pygments_lexer": "ipython3",
   "version": "3.11.7"
  }
 },
 "nbformat": 4,
 "nbformat_minor": 5
}
